[2025-06-26T13:12:06.827+0000] {local_task_job_runner.py:120} INFO - ::group::Pre task execution logs
[2025-06-26T13:12:06.861+0000] {taskinstance.py:2076} INFO - Dependencies all met for dep_context=non-requeueable deps ti=<TaskInstance: loan_credit_ml.training scheduled__2024-11-01T03:00:00+00:00 [queued]>
[2025-06-26T13:12:06.870+0000] {taskinstance.py:2076} INFO - Dependencies all met for dep_context=requeueable deps ti=<TaskInstance: loan_credit_ml.training scheduled__2024-11-01T03:00:00+00:00 [queued]>
[2025-06-26T13:12:06.872+0000] {taskinstance.py:2306} INFO - Starting attempt 1 of 2
[2025-06-26T13:12:06.891+0000] {taskinstance.py:2330} INFO - Executing <Task(PythonOperator): training> on 2024-11-01 03:00:00+00:00
[2025-06-26T13:12:06.904+0000] {standard_task_runner.py:90} INFO - Running: ['***', 'tasks', 'run', 'loan_credit_ml', 'training', 'scheduled__2024-11-01T03:00:00+00:00', '--job-id', '100', '--raw', '--subdir', 'DAGS_FOLDER/loan_ml_pipeline_dag.py', '--cfg-path', '/tmp/tmplv61r0af']
[2025-06-26T13:12:06.907+0000] {standard_task_runner.py:91} INFO - Job 100: Subtask training
[2025-06-26T13:12:06.908+0000] {logging_mixin.py:188} WARNING - /home/***/.local/lib/python3.12/site-packages/***/task/task_runner/standard_task_runner.py:61 DeprecationWarning: This process (pid=223) is multi-threaded, use of fork() may lead to deadlocks in the child.
[2025-06-26T13:12:06.909+0000] {standard_task_runner.py:63} INFO - Started process 233 to run task
[2025-06-26T13:12:06.989+0000] {task_command.py:426} INFO - Running <TaskInstance: loan_credit_ml.training scheduled__2024-11-01T03:00:00+00:00 [running]> on host f73c0c6d85d6
[2025-06-26T13:12:07.116+0000] {taskinstance.py:2648} INFO - Exporting env vars: AIRFLOW_CTX_DAG_OWNER='data-team' AIRFLOW_CTX_DAG_ID='loan_credit_ml' AIRFLOW_CTX_TASK_ID='training' AIRFLOW_CTX_EXECUTION_DATE='2024-11-01T03:00:00+00:00' AIRFLOW_CTX_TRY_NUMBER='1' AIRFLOW_CTX_DAG_RUN_ID='scheduled__2024-11-01T03:00:00+00:00'
[2025-06-26T13:12:07.118+0000] {taskinstance.py:430} INFO - ::endgroup::
[2025-06-26T13:12:10.646+0000] {logging_mixin.py:188} INFO - Fitting 3 folds for each of 10 candidates, totalling 30 fits
[2025-06-26T13:13:12.601+0000] {local_task_job_runner.py:310} WARNING - State of this instance has been externally set to None. Terminating instance.
[2025-06-26T13:13:12.608+0000] {local_task_job_runner.py:222} INFO - ::endgroup::
[2025-06-26T13:13:12.621+0000] {process_utils.py:132} INFO - Sending 15 to group 233. PIDs of all processes in the group: [233]
[2025-06-26T13:13:12.622+0000] {process_utils.py:87} INFO - Sending the signal 15 to group 233
[2025-06-26T13:13:12.637+0000] {taskinstance.py:2611} ERROR - Received SIGTERM. Terminating subprocesses.
[2025-06-26T13:13:12.640+0000] {taskinstance.py:441} INFO - ::group::Post task execution logs
[2025-06-26T13:13:12.663+0000] {taskinstance.py:2905} ERROR - Task failed with exception
Traceback (most recent call last):
  File "/home/airflow/.local/lib/python3.12/site-packages/airflow/models/taskinstance.py", line 465, in _execute_task
    result = _execute_callable(context=context, **execute_callable_kwargs)
             ^^^^^^^^^^^^^^^^^^^^^^^^^^^^^^^^^^^^^^^^^^^^^^^^^^^^^^^^^^^^^
  File "/home/airflow/.local/lib/python3.12/site-packages/airflow/models/taskinstance.py", line 432, in _execute_callable
    return execute_callable(context=context, **execute_callable_kwargs)
           ^^^^^^^^^^^^^^^^^^^^^^^^^^^^^^^^^^^^^^^^^^^^^^^^^^^^^^^^^^^^
  File "/home/airflow/.local/lib/python3.12/site-packages/airflow/models/baseoperator.py", line 401, in wrapper
    return func(self, *args, **kwargs)
           ^^^^^^^^^^^^^^^^^^^^^^^^^^^
  File "/home/airflow/.local/lib/python3.12/site-packages/airflow/operators/python.py", line 235, in execute
    return_value = self.execute_callable()
                   ^^^^^^^^^^^^^^^^^^^^^^^
  File "/home/airflow/.local/lib/python3.12/site-packages/airflow/operators/python.py", line 252, in execute_callable
    return self.python_callable(*self.op_args, **self.op_kwargs)
           ^^^^^^^^^^^^^^^^^^^^^^^^^^^^^^^^^^^^^^^^^^^^^^^^^^^^^
  File "/opt/airflow/dags/loan_ml_pipeline_dag.py", line 62, in training_task
    model, best_params, _ = modelling.train_xgboost_with_search(
                            ^^^^^^^^^^^^^^^^^^^^^^^^^^^^^^^^^^^^
  File "/opt/airflow/utils/modelling.py", line 150, in train_xgboost_with_search
    search.fit(X_tr, y_tr)
  File "/home/airflow/.local/lib/python3.12/site-packages/sklearn/base.py", line 1473, in wrapper
    return fit_method(estimator, *args, **kwargs)
           ^^^^^^^^^^^^^^^^^^^^^^^^^^^^^^^^^^^^^^
  File "/home/airflow/.local/lib/python3.12/site-packages/sklearn/model_selection/_search.py", line 968, in fit
    self._run_search(evaluate_candidates)
  File "/home/airflow/.local/lib/python3.12/site-packages/sklearn/model_selection/_search.py", line 1930, in _run_search
    evaluate_candidates(
  File "/home/airflow/.local/lib/python3.12/site-packages/sklearn/model_selection/_search.py", line 914, in evaluate_candidates
    out = parallel(
          ^^^^^^^^^
  File "/home/airflow/.local/lib/python3.12/site-packages/sklearn/utils/parallel.py", line 67, in __call__
    return super().__call__(iterable_with_config)
           ^^^^^^^^^^^^^^^^^^^^^^^^^^^^^^^^^^^^^^
  File "/home/airflow/.local/lib/python3.12/site-packages/joblib/parallel.py", line 1986, in __call__
    return output if self.return_generator else list(output)
                                                ^^^^^^^^^^^^
  File "/home/airflow/.local/lib/python3.12/site-packages/joblib/parallel.py", line 1914, in _get_sequential_output
    res = func(*args, **kwargs)
          ^^^^^^^^^^^^^^^^^^^^^
  File "/home/airflow/.local/lib/python3.12/site-packages/sklearn/utils/parallel.py", line 129, in __call__
    return self.function(*args, **kwargs)
           ^^^^^^^^^^^^^^^^^^^^^^^^^^^^^^
  File "/home/airflow/.local/lib/python3.12/site-packages/sklearn/model_selection/_validation.py", line 888, in _fit_and_score
    estimator.fit(X_train, y_train, **fit_params)
  File "/home/airflow/.local/lib/python3.12/site-packages/xgboost/core.py", line 730, in inner_f
    return func(**kwargs)
           ^^^^^^^^^^^^^^
  File "/home/airflow/.local/lib/python3.12/site-packages/xgboost/sklearn.py", line 1519, in fit
    self._Booster = train(
                    ^^^^^^
  File "/home/airflow/.local/lib/python3.12/site-packages/xgboost/core.py", line 730, in inner_f
    return func(**kwargs)
           ^^^^^^^^^^^^^^
  File "/home/airflow/.local/lib/python3.12/site-packages/xgboost/training.py", line 181, in train
    bst.update(dtrain, i, obj)
  File "/home/airflow/.local/lib/python3.12/site-packages/xgboost/core.py", line 2051, in update
    _LIB.XGBoosterUpdateOneIter(
  File "/home/airflow/.local/lib/python3.12/site-packages/airflow/models/taskinstance.py", line 2613, in signal_handler
    raise AirflowTaskTerminated("Task received SIGTERM signal")
airflow.exceptions.AirflowTaskTerminated: Task received SIGTERM signal
[2025-06-26T13:13:12.712+0000] {taskinstance.py:1206} INFO - Marking task as FAILED. dag_id=loan_credit_ml, task_id=training, run_id=scheduled__2024-11-01T03:00:00+00:00, execution_date=20241101T030000, start_date=20250626T131206, end_date=20250626T131312
[2025-06-26T13:13:12.741+0000] {standard_task_runner.py:110} ERROR - Failed to execute job 100 for task training ((psycopg2.errors.ForeignKeyViolation) insert or update on table "task_fail" violates foreign key constraint "task_fail_ti_fkey"
DETAIL:  Key (dag_id, task_id, run_id, map_index)=(loan_credit_ml, training, scheduled__2024-11-01T03:00:00+00:00, -1) is not present in table "task_instance".

[SQL: INSERT INTO task_fail (task_id, dag_id, run_id, map_index, start_date, end_date, duration) VALUES (%(task_id)s, %(dag_id)s, %(run_id)s, %(map_index)s, %(start_date)s, %(end_date)s, %(duration)s) RETURNING task_fail.id]
[parameters: {'task_id': 'training', 'dag_id': 'loan_credit_ml', 'run_id': 'scheduled__2024-11-01T03:00:00+00:00', 'map_index': -1, 'start_date': datetime.datetime(2025, 6, 26, 13, 12, 6, 862631, tzinfo=Timezone('UTC')), 'end_date': datetime.datetime(2025, 6, 26, 13, 13, 12, 711638, tzinfo=Timezone('UTC')), 'duration': 65}]
(Background on this error at: https://sqlalche.me/e/14/gkpj); 233)
[2025-06-26T13:13:12.838+0000] {process_utils.py:80} INFO - Process psutil.Process(pid=233, status='terminated', exitcode=1, started='13:12:05') (233) terminated with exit code 1
[2025-06-26T13:27:55.089+0000] {local_task_job_runner.py:120} INFO - ::group::Pre task execution logs
[2025-06-26T13:27:55.133+0000] {taskinstance.py:2076} INFO - Dependencies all met for dep_context=non-requeueable deps ti=<TaskInstance: loan_credit_ml.training scheduled__2024-11-01T03:00:00+00:00 [queued]>
[2025-06-26T13:27:55.143+0000] {taskinstance.py:2076} INFO - Dependencies all met for dep_context=requeueable deps ti=<TaskInstance: loan_credit_ml.training scheduled__2024-11-01T03:00:00+00:00 [queued]>
[2025-06-26T13:27:55.143+0000] {taskinstance.py:2306} INFO - Starting attempt 1 of 2
[2025-06-26T13:27:55.163+0000] {taskinstance.py:2330} INFO - Executing <Task(PythonOperator): training> on 2024-11-01 03:00:00+00:00
[2025-06-26T13:27:55.175+0000] {standard_task_runner.py:90} INFO - Running: ['***', 'tasks', 'run', 'loan_credit_ml', 'training', 'scheduled__2024-11-01T03:00:00+00:00', '--job-id', '114', '--raw', '--subdir', 'DAGS_FOLDER/loan_ml_pipeline_dag.py', '--cfg-path', '/tmp/tmppwncrw_w']
[2025-06-26T13:27:55.177+0000] {standard_task_runner.py:91} INFO - Job 114: Subtask training
[2025-06-26T13:27:55.179+0000] {logging_mixin.py:188} WARNING - /home/***/.local/lib/python3.12/site-packages/***/task/task_runner/standard_task_runner.py:61 DeprecationWarning: This process (pid=514) is multi-threaded, use of fork() may lead to deadlocks in the child.
[2025-06-26T13:27:55.180+0000] {standard_task_runner.py:63} INFO - Started process 524 to run task
[2025-06-26T13:27:55.237+0000] {task_command.py:426} INFO - Running <TaskInstance: loan_credit_ml.training scheduled__2024-11-01T03:00:00+00:00 [running]> on host 408a45b37ace
[2025-06-26T13:27:55.353+0000] {taskinstance.py:2648} INFO - Exporting env vars: AIRFLOW_CTX_DAG_OWNER='data-team' AIRFLOW_CTX_DAG_ID='loan_credit_ml' AIRFLOW_CTX_TASK_ID='training' AIRFLOW_CTX_EXECUTION_DATE='2024-11-01T03:00:00+00:00' AIRFLOW_CTX_TRY_NUMBER='1' AIRFLOW_CTX_DAG_RUN_ID='scheduled__2024-11-01T03:00:00+00:00'
[2025-06-26T13:27:55.355+0000] {taskinstance.py:430} INFO - ::endgroup::
[2025-06-26T13:27:58.282+0000] {logging_mixin.py:188} INFO - Fitting 3 folds for each of 10 candidates, totalling 30 fits
[2025-06-26T13:29:52.131+0000] {job.py:218} ERROR - Job heartbeat got an exception
Traceback (most recent call last):
  File "/home/airflow/.local/lib/python3.12/site-packages/sqlalchemy/engine/base.py", line 3371, in _wrap_pool_connect
    return fn()
           ^^^^
  File "/home/airflow/.local/lib/python3.12/site-packages/sqlalchemy/pool/base.py", line 327, in connect
    return _ConnectionFairy._checkout(self)
           ^^^^^^^^^^^^^^^^^^^^^^^^^^^^^^^^
  File "/home/airflow/.local/lib/python3.12/site-packages/sqlalchemy/pool/base.py", line 894, in _checkout
    fairy = _ConnectionRecord.checkout(pool)
            ^^^^^^^^^^^^^^^^^^^^^^^^^^^^^^^^
  File "/home/airflow/.local/lib/python3.12/site-packages/sqlalchemy/pool/base.py", line 493, in checkout
    rec = pool._do_get()
          ^^^^^^^^^^^^^^
  File "/home/airflow/.local/lib/python3.12/site-packages/sqlalchemy/pool/impl.py", line 256, in _do_get
    return self._create_connection()
           ^^^^^^^^^^^^^^^^^^^^^^^^^
  File "/home/airflow/.local/lib/python3.12/site-packages/sqlalchemy/pool/base.py", line 273, in _create_connection
    return _ConnectionRecord(self)
           ^^^^^^^^^^^^^^^^^^^^^^^
  File "/home/airflow/.local/lib/python3.12/site-packages/sqlalchemy/pool/base.py", line 388, in __init__
    self.__connect()
  File "/home/airflow/.local/lib/python3.12/site-packages/sqlalchemy/pool/base.py", line 690, in __connect
    with util.safe_reraise():
  File "/home/airflow/.local/lib/python3.12/site-packages/sqlalchemy/util/langhelpers.py", line 70, in __exit__
    compat.raise_(
  File "/home/airflow/.local/lib/python3.12/site-packages/sqlalchemy/util/compat.py", line 211, in raise_
    raise exception
  File "/home/airflow/.local/lib/python3.12/site-packages/sqlalchemy/pool/base.py", line 686, in __connect
    self.dbapi_connection = connection = pool._invoke_creator(self)
                                         ^^^^^^^^^^^^^^^^^^^^^^^^^^
  File "/home/airflow/.local/lib/python3.12/site-packages/sqlalchemy/engine/create.py", line 574, in connect
    return dialect.connect(*cargs, **cparams)
           ^^^^^^^^^^^^^^^^^^^^^^^^^^^^^^^^^^
  File "/home/airflow/.local/lib/python3.12/site-packages/sqlalchemy/engine/default.py", line 598, in connect
    return self.dbapi.connect(*cargs, **cparams)
           ^^^^^^^^^^^^^^^^^^^^^^^^^^^^^^^^^^^^^
  File "/home/airflow/.local/lib/python3.12/site-packages/psycopg2/__init__.py", line 122, in connect
    conn = _connect(dsn, connection_factory=connection_factory, **kwasync)
           ^^^^^^^^^^^^^^^^^^^^^^^^^^^^^^^^^^^^^^^^^^^^^^^^^^^^^^^^^^^^^^^
psycopg2.OperationalError: could not translate host name "postgres" to address: Temporary failure in name resolution


The above exception was the direct cause of the following exception:

Traceback (most recent call last):
  File "/home/airflow/.local/lib/python3.12/site-packages/airflow/jobs/job.py", line 192, in heartbeat
    self._merge_from(Job._fetch_from_db(self, session))
                     ^^^^^^^^^^^^^^^^^^^^^^^^^^^^^^^^^
  File "/home/airflow/.local/lib/python3.12/site-packages/airflow/api_internal/internal_api_call.py", line 115, in wrapper
    return func(*args, **kwargs)
           ^^^^^^^^^^^^^^^^^^^^^
  File "/home/airflow/.local/lib/python3.12/site-packages/airflow/utils/session.py", line 76, in wrapper
    return func(*args, **kwargs)
           ^^^^^^^^^^^^^^^^^^^^^
  File "/home/airflow/.local/lib/python3.12/site-packages/airflow/utils/retries.py", line 89, in wrapped_function
    for attempt in run_with_db_retries(max_retries=retries, logger=logger, **retry_kwargs):
  File "/home/airflow/.local/lib/python3.12/site-packages/tenacity/__init__.py", line 435, in __iter__
    do = self.iter(retry_state=retry_state)
         ^^^^^^^^^^^^^^^^^^^^^^^^^^^^^^^^^^
  File "/home/airflow/.local/lib/python3.12/site-packages/tenacity/__init__.py", line 368, in iter
    result = action(retry_state)
             ^^^^^^^^^^^^^^^^^^^
  File "/home/airflow/.local/lib/python3.12/site-packages/tenacity/__init__.py", line 410, in exc_check
    raise retry_exc.reraise()
          ^^^^^^^^^^^^^^^^^^^
  File "/home/airflow/.local/lib/python3.12/site-packages/tenacity/__init__.py", line 183, in reraise
    raise self.last_attempt.result()
          ^^^^^^^^^^^^^^^^^^^^^^^^^^
  File "/usr/local/lib/python3.12/concurrent/futures/_base.py", line 449, in result
    return self.__get_result()
           ^^^^^^^^^^^^^^^^^^^
  File "/usr/local/lib/python3.12/concurrent/futures/_base.py", line 401, in __get_result
    raise self._exception
  File "/home/airflow/.local/lib/python3.12/site-packages/airflow/utils/retries.py", line 98, in wrapped_function
    return func(*args, **kwargs)
           ^^^^^^^^^^^^^^^^^^^^^
  File "/home/airflow/.local/lib/python3.12/site-packages/airflow/jobs/job.py", line 316, in _fetch_from_db
    session.merge(job)
  File "/home/airflow/.local/lib/python3.12/site-packages/sqlalchemy/orm/session.py", line 3056, in merge
    return self._merge(
           ^^^^^^^^^^^^
  File "/home/airflow/.local/lib/python3.12/site-packages/sqlalchemy/orm/session.py", line 3136, in _merge
    merged = self.get(
             ^^^^^^^^^
  File "/home/airflow/.local/lib/python3.12/site-packages/sqlalchemy/orm/session.py", line 2853, in get
    return self._get_impl(
           ^^^^^^^^^^^^^^^
  File "/home/airflow/.local/lib/python3.12/site-packages/sqlalchemy/orm/session.py", line 2975, in _get_impl
    return db_load_fn(
           ^^^^^^^^^^^
  File "/home/airflow/.local/lib/python3.12/site-packages/sqlalchemy/orm/loading.py", line 530, in load_on_pk_identity
    session.execute(
  File "/home/airflow/.local/lib/python3.12/site-packages/sqlalchemy/orm/session.py", line 1716, in execute
    conn = self._connection_for_bind(bind)
           ^^^^^^^^^^^^^^^^^^^^^^^^^^^^^^^
  File "/home/airflow/.local/lib/python3.12/site-packages/sqlalchemy/orm/session.py", line 1555, in _connection_for_bind
    return self._transaction._connection_for_bind(
           ^^^^^^^^^^^^^^^^^^^^^^^^^^^^^^^^^^^^^^^
  File "/home/airflow/.local/lib/python3.12/site-packages/sqlalchemy/orm/session.py", line 750, in _connection_for_bind
    conn = bind.connect()
           ^^^^^^^^^^^^^^
  File "/home/airflow/.local/lib/python3.12/site-packages/sqlalchemy/future/engine.py", line 412, in connect
    return super(Engine, self).connect()
           ^^^^^^^^^^^^^^^^^^^^^^^^^^^^^
  File "/home/airflow/.local/lib/python3.12/site-packages/sqlalchemy/engine/base.py", line 3325, in connect
    return self._connection_cls(self, close_with_result=close_with_result)
           ^^^^^^^^^^^^^^^^^^^^^^^^^^^^^^^^^^^^^^^^^^^^^^^^^^^^^^^^^^^^^^^
  File "/home/airflow/.local/lib/python3.12/site-packages/sqlalchemy/engine/base.py", line 96, in __init__
    else engine.raw_connection()
         ^^^^^^^^^^^^^^^^^^^^^^^
  File "/home/airflow/.local/lib/python3.12/site-packages/sqlalchemy/engine/base.py", line 3404, in raw_connection
    return self._wrap_pool_connect(self.pool.connect, _connection)
           ^^^^^^^^^^^^^^^^^^^^^^^^^^^^^^^^^^^^^^^^^^^^^^^^^^^^^^^
  File "/home/airflow/.local/lib/python3.12/site-packages/sqlalchemy/engine/base.py", line 3374, in _wrap_pool_connect
    Connection._handle_dbapi_exception_noconnection(
  File "/home/airflow/.local/lib/python3.12/site-packages/sqlalchemy/engine/base.py", line 2208, in _handle_dbapi_exception_noconnection
    util.raise_(
  File "/home/airflow/.local/lib/python3.12/site-packages/sqlalchemy/util/compat.py", line 211, in raise_
    raise exception
  File "/home/airflow/.local/lib/python3.12/site-packages/sqlalchemy/engine/base.py", line 3371, in _wrap_pool_connect
    return fn()
           ^^^^
  File "/home/airflow/.local/lib/python3.12/site-packages/sqlalchemy/pool/base.py", line 327, in connect
    return _ConnectionFairy._checkout(self)
           ^^^^^^^^^^^^^^^^^^^^^^^^^^^^^^^^
  File "/home/airflow/.local/lib/python3.12/site-packages/sqlalchemy/pool/base.py", line 894, in _checkout
    fairy = _ConnectionRecord.checkout(pool)
            ^^^^^^^^^^^^^^^^^^^^^^^^^^^^^^^^
  File "/home/airflow/.local/lib/python3.12/site-packages/sqlalchemy/pool/base.py", line 493, in checkout
    rec = pool._do_get()
          ^^^^^^^^^^^^^^
  File "/home/airflow/.local/lib/python3.12/site-packages/sqlalchemy/pool/impl.py", line 256, in _do_get
    return self._create_connection()
           ^^^^^^^^^^^^^^^^^^^^^^^^^
  File "/home/airflow/.local/lib/python3.12/site-packages/sqlalchemy/pool/base.py", line 273, in _create_connection
    return _ConnectionRecord(self)
           ^^^^^^^^^^^^^^^^^^^^^^^
  File "/home/airflow/.local/lib/python3.12/site-packages/sqlalchemy/pool/base.py", line 388, in __init__
    self.__connect()
  File "/home/airflow/.local/lib/python3.12/site-packages/sqlalchemy/pool/base.py", line 690, in __connect
    with util.safe_reraise():
  File "/home/airflow/.local/lib/python3.12/site-packages/sqlalchemy/util/langhelpers.py", line 70, in __exit__
    compat.raise_(
  File "/home/airflow/.local/lib/python3.12/site-packages/sqlalchemy/util/compat.py", line 211, in raise_
    raise exception
  File "/home/airflow/.local/lib/python3.12/site-packages/sqlalchemy/pool/base.py", line 686, in __connect
    self.dbapi_connection = connection = pool._invoke_creator(self)
                                         ^^^^^^^^^^^^^^^^^^^^^^^^^^
  File "/home/airflow/.local/lib/python3.12/site-packages/sqlalchemy/engine/create.py", line 574, in connect
    return dialect.connect(*cargs, **cparams)
           ^^^^^^^^^^^^^^^^^^^^^^^^^^^^^^^^^^
  File "/home/airflow/.local/lib/python3.12/site-packages/sqlalchemy/engine/default.py", line 598, in connect
    return self.dbapi.connect(*cargs, **cparams)
           ^^^^^^^^^^^^^^^^^^^^^^^^^^^^^^^^^^^^^
  File "/home/airflow/.local/lib/python3.12/site-packages/psycopg2/__init__.py", line 122, in connect
    conn = _connect(dsn, connection_factory=connection_factory, **kwasync)
           ^^^^^^^^^^^^^^^^^^^^^^^^^^^^^^^^^^^^^^^^^^^^^^^^^^^^^^^^^^^^^^^
sqlalchemy.exc.OperationalError: (psycopg2.OperationalError) could not translate host name "postgres" to address: Temporary failure in name resolution

(Background on this error at: https://sqlalche.me/e/14/e3q8)
[2025-06-26T13:29:53.760+0000] {job.py:226} ERROR - Job heartbeat failed with error. Scheduler is in unhealthy state
[2025-06-26T13:31:15.415+0000] {job.py:226} ERROR - Job heartbeat failed with error. Scheduler is in unhealthy state
[2025-06-26T13:32:34.012+0000] {job.py:226} ERROR - Job heartbeat failed with error. Scheduler is in unhealthy state
[2025-06-26T13:33:46.347+0000] {job.py:226} ERROR - Job heartbeat failed with error. Scheduler is in unhealthy state
[2025-06-26T13:34:28.567+0000] {logging_mixin.py:188} INFO - ✓ Model artefact saved → model_bank/credit_model_2024_11_01.pkl
[2025-06-26T13:34:29.300+0000] {python.py:237} INFO - Done. Returned value was: None
[2025-06-26T13:34:29.312+0000] {taskinstance.py:441} INFO - ::group::Post task execution logs
[2025-06-26T13:35:01.023+0000] {taskinstance.py:2905} ERROR - Task failed with exception
Traceback (most recent call last):
  File "/home/airflow/.local/lib/python3.12/site-packages/sqlalchemy/engine/base.py", line 3371, in _wrap_pool_connect
    return fn()
           ^^^^
  File "/home/airflow/.local/lib/python3.12/site-packages/sqlalchemy/pool/base.py", line 327, in connect
    return _ConnectionFairy._checkout(self)
           ^^^^^^^^^^^^^^^^^^^^^^^^^^^^^^^^
  File "/home/airflow/.local/lib/python3.12/site-packages/sqlalchemy/pool/base.py", line 894, in _checkout
    fairy = _ConnectionRecord.checkout(pool)
            ^^^^^^^^^^^^^^^^^^^^^^^^^^^^^^^^
  File "/home/airflow/.local/lib/python3.12/site-packages/sqlalchemy/pool/base.py", line 493, in checkout
    rec = pool._do_get()
          ^^^^^^^^^^^^^^
  File "/home/airflow/.local/lib/python3.12/site-packages/sqlalchemy/pool/impl.py", line 256, in _do_get
    return self._create_connection()
           ^^^^^^^^^^^^^^^^^^^^^^^^^
  File "/home/airflow/.local/lib/python3.12/site-packages/sqlalchemy/pool/base.py", line 273, in _create_connection
    return _ConnectionRecord(self)
           ^^^^^^^^^^^^^^^^^^^^^^^
  File "/home/airflow/.local/lib/python3.12/site-packages/sqlalchemy/pool/base.py", line 388, in __init__
    self.__connect()
  File "/home/airflow/.local/lib/python3.12/site-packages/sqlalchemy/pool/base.py", line 690, in __connect
    with util.safe_reraise():
  File "/home/airflow/.local/lib/python3.12/site-packages/sqlalchemy/util/langhelpers.py", line 70, in __exit__
    compat.raise_(
  File "/home/airflow/.local/lib/python3.12/site-packages/sqlalchemy/util/compat.py", line 211, in raise_
    raise exception
  File "/home/airflow/.local/lib/python3.12/site-packages/sqlalchemy/pool/base.py", line 686, in __connect
    self.dbapi_connection = connection = pool._invoke_creator(self)
                                         ^^^^^^^^^^^^^^^^^^^^^^^^^^
  File "/home/airflow/.local/lib/python3.12/site-packages/sqlalchemy/engine/create.py", line 574, in connect
    return dialect.connect(*cargs, **cparams)
           ^^^^^^^^^^^^^^^^^^^^^^^^^^^^^^^^^^
  File "/home/airflow/.local/lib/python3.12/site-packages/sqlalchemy/engine/default.py", line 598, in connect
    return self.dbapi.connect(*cargs, **cparams)
           ^^^^^^^^^^^^^^^^^^^^^^^^^^^^^^^^^^^^^
  File "/home/airflow/.local/lib/python3.12/site-packages/psycopg2/__init__.py", line 122, in connect
    conn = _connect(dsn, connection_factory=connection_factory, **kwasync)
           ^^^^^^^^^^^^^^^^^^^^^^^^^^^^^^^^^^^^^^^^^^^^^^^^^^^^^^^^^^^^^^^
psycopg2.OperationalError: could not translate host name "postgres" to address: Temporary failure in name resolution


The above exception was the direct cause of the following exception:

Traceback (most recent call last):
  File "/home/airflow/.local/lib/python3.12/site-packages/airflow/models/taskinstance.py", line 2481, in _run_raw_task
    self.refresh_from_db(lock_for_update=True, session=session)
  File "/home/airflow/.local/lib/python3.12/site-packages/airflow/utils/session.py", line 76, in wrapper
    return func(*args, **kwargs)
           ^^^^^^^^^^^^^^^^^^^^^
  File "/home/airflow/.local/lib/python3.12/site-packages/airflow/models/taskinstance.py", line 1821, in refresh_from_db
    _refresh_from_db(task_instance=self, session=session, lock_for_update=lock_for_update)
  File "/home/airflow/.local/lib/python3.12/site-packages/airflow/models/taskinstance.py", line 510, in _refresh_from_db
    ti = TaskInstance.get_task_instance(
         ^^^^^^^^^^^^^^^^^^^^^^^^^^^^^^^
  File "/home/airflow/.local/lib/python3.12/site-packages/airflow/api_internal/internal_api_call.py", line 115, in wrapper
    return func(*args, **kwargs)
           ^^^^^^^^^^^^^^^^^^^^^
  File "/home/airflow/.local/lib/python3.12/site-packages/airflow/utils/session.py", line 76, in wrapper
    return func(*args, **kwargs)
           ^^^^^^^^^^^^^^^^^^^^^
  File "/home/airflow/.local/lib/python3.12/site-packages/airflow/models/taskinstance.py", line 1803, in get_task_instance
    for attempt in run_with_db_retries(logger=cls.logger()):
  File "/home/airflow/.local/lib/python3.12/site-packages/tenacity/__init__.py", line 435, in __iter__
    do = self.iter(retry_state=retry_state)
         ^^^^^^^^^^^^^^^^^^^^^^^^^^^^^^^^^^
  File "/home/airflow/.local/lib/python3.12/site-packages/tenacity/__init__.py", line 368, in iter
    result = action(retry_state)
             ^^^^^^^^^^^^^^^^^^^
  File "/home/airflow/.local/lib/python3.12/site-packages/tenacity/__init__.py", line 410, in exc_check
    raise retry_exc.reraise()
          ^^^^^^^^^^^^^^^^^^^
  File "/home/airflow/.local/lib/python3.12/site-packages/tenacity/__init__.py", line 183, in reraise
    raise self.last_attempt.result()
          ^^^^^^^^^^^^^^^^^^^^^^^^^^
  File "/usr/local/lib/python3.12/concurrent/futures/_base.py", line 449, in result
    return self.__get_result()
           ^^^^^^^^^^^^^^^^^^^
  File "/usr/local/lib/python3.12/concurrent/futures/_base.py", line 401, in __get_result
    raise self._exception
  File "/home/airflow/.local/lib/python3.12/site-packages/airflow/models/taskinstance.py", line 1805, in get_task_instance
    return query.with_for_update().one_or_none()
           ^^^^^^^^^^^^^^^^^^^^^^^^^^^^^^^^^^^^^
  File "/home/airflow/.local/lib/python3.12/site-packages/sqlalchemy/orm/query.py", line 2850, in one_or_none
    return self._iter().one_or_none()
           ^^^^^^^^^^^^
  File "/home/airflow/.local/lib/python3.12/site-packages/sqlalchemy/orm/query.py", line 2916, in _iter
    result = self.session.execute(
             ^^^^^^^^^^^^^^^^^^^^^
  File "/home/airflow/.local/lib/python3.12/site-packages/sqlalchemy/orm/session.py", line 1716, in execute
    conn = self._connection_for_bind(bind)
           ^^^^^^^^^^^^^^^^^^^^^^^^^^^^^^^
  File "/home/airflow/.local/lib/python3.12/site-packages/sqlalchemy/orm/session.py", line 1555, in _connection_for_bind
    return self._transaction._connection_for_bind(
           ^^^^^^^^^^^^^^^^^^^^^^^^^^^^^^^^^^^^^^^
  File "/home/airflow/.local/lib/python3.12/site-packages/sqlalchemy/orm/session.py", line 750, in _connection_for_bind
    conn = bind.connect()
           ^^^^^^^^^^^^^^
  File "/home/airflow/.local/lib/python3.12/site-packages/sqlalchemy/future/engine.py", line 412, in connect
    return super(Engine, self).connect()
           ^^^^^^^^^^^^^^^^^^^^^^^^^^^^^
  File "/home/airflow/.local/lib/python3.12/site-packages/sqlalchemy/engine/base.py", line 3325, in connect
    return self._connection_cls(self, close_with_result=close_with_result)
           ^^^^^^^^^^^^^^^^^^^^^^^^^^^^^^^^^^^^^^^^^^^^^^^^^^^^^^^^^^^^^^^
  File "/home/airflow/.local/lib/python3.12/site-packages/sqlalchemy/engine/base.py", line 96, in __init__
    else engine.raw_connection()
         ^^^^^^^^^^^^^^^^^^^^^^^
  File "/home/airflow/.local/lib/python3.12/site-packages/sqlalchemy/engine/base.py", line 3404, in raw_connection
    return self._wrap_pool_connect(self.pool.connect, _connection)
           ^^^^^^^^^^^^^^^^^^^^^^^^^^^^^^^^^^^^^^^^^^^^^^^^^^^^^^^
  File "/home/airflow/.local/lib/python3.12/site-packages/sqlalchemy/engine/base.py", line 3374, in _wrap_pool_connect
    Connection._handle_dbapi_exception_noconnection(
  File "/home/airflow/.local/lib/python3.12/site-packages/sqlalchemy/engine/base.py", line 2208, in _handle_dbapi_exception_noconnection
    util.raise_(
  File "/home/airflow/.local/lib/python3.12/site-packages/sqlalchemy/util/compat.py", line 211, in raise_
    raise exception
  File "/home/airflow/.local/lib/python3.12/site-packages/sqlalchemy/engine/base.py", line 3371, in _wrap_pool_connect
    return fn()
           ^^^^
  File "/home/airflow/.local/lib/python3.12/site-packages/sqlalchemy/pool/base.py", line 327, in connect
    return _ConnectionFairy._checkout(self)
           ^^^^^^^^^^^^^^^^^^^^^^^^^^^^^^^^
  File "/home/airflow/.local/lib/python3.12/site-packages/sqlalchemy/pool/base.py", line 894, in _checkout
    fairy = _ConnectionRecord.checkout(pool)
            ^^^^^^^^^^^^^^^^^^^^^^^^^^^^^^^^
  File "/home/airflow/.local/lib/python3.12/site-packages/sqlalchemy/pool/base.py", line 493, in checkout
    rec = pool._do_get()
          ^^^^^^^^^^^^^^
  File "/home/airflow/.local/lib/python3.12/site-packages/sqlalchemy/pool/impl.py", line 256, in _do_get
    return self._create_connection()
           ^^^^^^^^^^^^^^^^^^^^^^^^^
  File "/home/airflow/.local/lib/python3.12/site-packages/sqlalchemy/pool/base.py", line 273, in _create_connection
    return _ConnectionRecord(self)
           ^^^^^^^^^^^^^^^^^^^^^^^
  File "/home/airflow/.local/lib/python3.12/site-packages/sqlalchemy/pool/base.py", line 388, in __init__
    self.__connect()
  File "/home/airflow/.local/lib/python3.12/site-packages/sqlalchemy/pool/base.py", line 690, in __connect
    with util.safe_reraise():
  File "/home/airflow/.local/lib/python3.12/site-packages/sqlalchemy/util/langhelpers.py", line 70, in __exit__
    compat.raise_(
  File "/home/airflow/.local/lib/python3.12/site-packages/sqlalchemy/util/compat.py", line 211, in raise_
    raise exception
  File "/home/airflow/.local/lib/python3.12/site-packages/sqlalchemy/pool/base.py", line 686, in __connect
    self.dbapi_connection = connection = pool._invoke_creator(self)
                                         ^^^^^^^^^^^^^^^^^^^^^^^^^^
  File "/home/airflow/.local/lib/python3.12/site-packages/sqlalchemy/engine/create.py", line 574, in connect
    return dialect.connect(*cargs, **cparams)
           ^^^^^^^^^^^^^^^^^^^^^^^^^^^^^^^^^^
  File "/home/airflow/.local/lib/python3.12/site-packages/sqlalchemy/engine/default.py", line 598, in connect
    return self.dbapi.connect(*cargs, **cparams)
           ^^^^^^^^^^^^^^^^^^^^^^^^^^^^^^^^^^^^^
  File "/home/airflow/.local/lib/python3.12/site-packages/psycopg2/__init__.py", line 122, in connect
    conn = _connect(dsn, connection_factory=connection_factory, **kwasync)
           ^^^^^^^^^^^^^^^^^^^^^^^^^^^^^^^^^^^^^^^^^^^^^^^^^^^^^^^^^^^^^^^
sqlalchemy.exc.OperationalError: (psycopg2.OperationalError) could not translate host name "postgres" to address: Temporary failure in name resolution

(Background on this error at: https://sqlalche.me/e/14/e3q8)
[2025-06-26T13:35:02.997+0000] {job.py:226} ERROR - Job heartbeat failed with error. Scheduler is in unhealthy state
[2025-06-26T13:35:11.130+0000] {taskinstance.py:1206} INFO - Marking task as UP_FOR_RETRY. dag_id=loan_credit_ml, task_id=training, run_id=scheduled__2024-11-01T03:00:00+00:00, execution_date=20241101T030000, start_date=20250626T132755, end_date=20250626T133511
[2025-06-26T13:35:11.656+0000] {standard_task_runner.py:110} ERROR - Failed to execute job 114 for task training ((psycopg2.OperationalError) could not translate host name "postgres" to address: Temporary failure in name resolution

(Background on this error at: https://sqlalche.me/e/14/e3q8); 524)
[2025-06-26T13:35:11.971+0000] {local_task_job_runner.py:240} INFO - Task exited with return code 1
[2025-06-26T13:35:12.396+0000] {taskinstance.py:3503} INFO - 0 downstream tasks scheduled from follow-on schedule check
[2025-06-26T13:35:12.404+0000] {local_task_job_runner.py:222} INFO - ::endgroup::
[2025-06-26T14:02:48.712+0000] {local_task_job_runner.py:120} INFO - ::group::Pre task execution logs
[2025-06-26T14:02:48.781+0000] {taskinstance.py:2076} INFO - Dependencies all met for dep_context=non-requeueable deps ti=<TaskInstance: loan_credit_ml.training scheduled__2024-11-01T03:00:00+00:00 [queued]>
[2025-06-26T14:02:48.790+0000] {taskinstance.py:2076} INFO - Dependencies all met for dep_context=requeueable deps ti=<TaskInstance: loan_credit_ml.training scheduled__2024-11-01T03:00:00+00:00 [queued]>
[2025-06-26T14:02:48.791+0000] {taskinstance.py:2306} INFO - Starting attempt 1 of 2
[2025-06-26T14:02:48.814+0000] {taskinstance.py:2330} INFO - Executing <Task(PythonOperator): training> on 2024-11-01 03:00:00+00:00
[2025-06-26T14:02:48.826+0000] {standard_task_runner.py:90} INFO - Running: ['***', 'tasks', 'run', 'loan_credit_ml', 'training', 'scheduled__2024-11-01T03:00:00+00:00', '--job-id', '9', '--raw', '--subdir', 'DAGS_FOLDER/loan_ml_pipeline_dag.py', '--cfg-path', '/tmp/tmpmgtyf2al']
[2025-06-26T14:02:48.830+0000] {standard_task_runner.py:91} INFO - Job 9: Subtask training
[2025-06-26T14:02:48.832+0000] {logging_mixin.py:188} WARNING - /home/***/.local/lib/python3.12/site-packages/***/task/task_runner/standard_task_runner.py:61 DeprecationWarning: This process (pid=493) is multi-threaded, use of fork() may lead to deadlocks in the child.
[2025-06-26T14:02:48.833+0000] {standard_task_runner.py:63} INFO - Started process 503 to run task
[2025-06-26T14:02:48.899+0000] {task_command.py:426} INFO - Running <TaskInstance: loan_credit_ml.training scheduled__2024-11-01T03:00:00+00:00 [running]> on host ab9233100691
[2025-06-26T14:02:49.014+0000] {taskinstance.py:2648} INFO - Exporting env vars: AIRFLOW_CTX_DAG_OWNER='data-team' AIRFLOW_CTX_DAG_ID='loan_credit_ml' AIRFLOW_CTX_TASK_ID='training' AIRFLOW_CTX_EXECUTION_DATE='2024-11-01T03:00:00+00:00' AIRFLOW_CTX_TRY_NUMBER='1' AIRFLOW_CTX_DAG_RUN_ID='scheduled__2024-11-01T03:00:00+00:00'
[2025-06-26T14:02:49.015+0000] {taskinstance.py:430} INFO - ::endgroup::
[2025-06-26T14:02:49.051+0000] {logging_mixin.py:188} INFO - Date config for this run: {'train_test_start_date': '2023-02-01', 'train_test_end_date': '2024-07-31', 'oot_start_date': '2024-08-01', 'oot_end_date': '2024-10-31', 'train_test_ratio': 0.8, 'model_train_date_str': '2024-11-01'}
[2025-06-26T14:02:52.385+0000] {logging_mixin.py:188} INFO - Fitting 3 folds for each of 10 candidates, totalling 30 fits
[2025-06-26T14:06:28.794+0000] {logging_mixin.py:188} INFO - ✓ Model artefact saved → model_bank/credit_model_2024_11_01.pkl
[2025-06-26T14:06:29.147+0000] {python.py:237} INFO - Done. Returned value was: None
[2025-06-26T14:06:29.150+0000] {taskinstance.py:441} INFO - ::group::Post task execution logs
[2025-06-26T14:06:29.275+0000] {taskinstance.py:1206} INFO - Marking task as SUCCESS. dag_id=loan_credit_ml, task_id=training, run_id=scheduled__2024-11-01T03:00:00+00:00, execution_date=20241101T030000, start_date=20250626T140248, end_date=20250626T140629
[2025-06-26T14:06:29.431+0000] {local_task_job_runner.py:240} INFO - Task exited with return code 0
[2025-06-26T14:06:29.600+0000] {taskinstance.py:3503} INFO - 1 downstream tasks scheduled from follow-on schedule check
[2025-06-26T14:06:29.604+0000] {local_task_job_runner.py:222} INFO - ::endgroup::
[2025-06-26T14:18:15.568+0000] {local_task_job_runner.py:120} INFO - ::group::Pre task execution logs
[2025-06-26T14:18:15.638+0000] {taskinstance.py:2076} INFO - Dependencies all met for dep_context=non-requeueable deps ti=<TaskInstance: loan_credit_ml.training scheduled__2024-11-01T03:00:00+00:00 [queued]>
[2025-06-26T14:18:15.657+0000] {taskinstance.py:2076} INFO - Dependencies all met for dep_context=requeueable deps ti=<TaskInstance: loan_credit_ml.training scheduled__2024-11-01T03:00:00+00:00 [queued]>
[2025-06-26T14:18:15.658+0000] {taskinstance.py:2306} INFO - Starting attempt 1 of 2
[2025-06-26T14:18:15.684+0000] {taskinstance.py:2330} INFO - Executing <Task(PythonOperator): training> on 2024-11-01 03:00:00+00:00
[2025-06-26T14:18:15.717+0000] {standard_task_runner.py:90} INFO - Running: ['***', 'tasks', 'run', 'loan_credit_ml', 'training', 'scheduled__2024-11-01T03:00:00+00:00', '--job-id', '9', '--raw', '--subdir', 'DAGS_FOLDER/loan_ml_pipeline_dag.py', '--cfg-path', '/tmp/tmpvplym4g4']
[2025-06-26T14:18:15.724+0000] {standard_task_runner.py:91} INFO - Job 9: Subtask training
[2025-06-26T14:18:15.725+0000] {logging_mixin.py:188} WARNING - /home/***/.local/lib/python3.12/site-packages/***/task/task_runner/standard_task_runner.py:61 DeprecationWarning: This process (pid=479) is multi-threaded, use of fork() may lead to deadlocks in the child.
[2025-06-26T14:18:15.727+0000] {standard_task_runner.py:63} INFO - Started process 489 to run task
[2025-06-26T14:18:15.853+0000] {task_command.py:426} INFO - Running <TaskInstance: loan_credit_ml.training scheduled__2024-11-01T03:00:00+00:00 [running]> on host 0192db86dfc6
[2025-06-26T14:18:16.119+0000] {taskinstance.py:2648} INFO - Exporting env vars: AIRFLOW_CTX_DAG_OWNER='data-team' AIRFLOW_CTX_DAG_ID='loan_credit_ml' AIRFLOW_CTX_TASK_ID='training' AIRFLOW_CTX_EXECUTION_DATE='2024-11-01T03:00:00+00:00' AIRFLOW_CTX_TRY_NUMBER='1' AIRFLOW_CTX_DAG_RUN_ID='scheduled__2024-11-01T03:00:00+00:00'
[2025-06-26T14:18:16.123+0000] {taskinstance.py:430} INFO - ::endgroup::
[2025-06-26T14:18:16.159+0000] {logging_mixin.py:188} INFO - Date config for this run: {'train_test_start_date': '2023-02-01', 'train_test_end_date': '2024-07-31', 'oot_start_date': '2024-08-01', 'oot_end_date': '2024-10-31', 'train_test_ratio': 0.8, 'model_train_date_str': '2024-11-01'}
[2025-06-26T14:18:19.249+0000] {logging_mixin.py:188} INFO - Fitting 3 folds for each of 10 candidates, totalling 30 fits
[2025-06-26T14:21:24.433+0000] {logging_mixin.py:188} INFO - ✓ Model artefact saved → model_bank/credit_model_2024_11_01.pkl
[2025-06-26T14:21:24.868+0000] {python.py:237} INFO - Done. Returned value was: None
[2025-06-26T14:21:24.870+0000] {taskinstance.py:441} INFO - ::group::Post task execution logs
[2025-06-26T14:21:24.988+0000] {taskinstance.py:1206} INFO - Marking task as SUCCESS. dag_id=loan_credit_ml, task_id=training, run_id=scheduled__2024-11-01T03:00:00+00:00, execution_date=20241101T030000, start_date=20250626T141815, end_date=20250626T142124
[2025-06-26T14:21:25.171+0000] {local_task_job_runner.py:240} INFO - Task exited with return code 0
[2025-06-26T14:21:25.316+0000] {taskinstance.py:3503} INFO - 1 downstream tasks scheduled from follow-on schedule check
[2025-06-26T14:21:25.323+0000] {local_task_job_runner.py:222} INFO - ::endgroup::
