[2025-06-26T14:10:12.041+0000] {local_task_job_runner.py:120} INFO - ::group::Pre task execution logs
[2025-06-26T14:10:12.076+0000] {taskinstance.py:2076} INFO - Dependencies all met for dep_context=non-requeueable deps ti=<TaskInstance: loan_credit_ml.training scheduled__2025-01-01T03:00:00+00:00 [queued]>
[2025-06-26T14:10:12.088+0000] {taskinstance.py:2076} INFO - Dependencies all met for dep_context=requeueable deps ti=<TaskInstance: loan_credit_ml.training scheduled__2025-01-01T03:00:00+00:00 [queued]>
[2025-06-26T14:10:12.089+0000] {taskinstance.py:2306} INFO - Starting attempt 1 of 2
[2025-06-26T14:10:12.107+0000] {taskinstance.py:2330} INFO - Executing <Task(PythonOperator): training> on 2025-01-01 03:00:00+00:00
[2025-06-26T14:10:12.125+0000] {standard_task_runner.py:90} INFO - Running: ['***', 'tasks', 'run', 'loan_credit_ml', 'training', 'scheduled__2025-01-01T03:00:00+00:00', '--job-id', '17', '--raw', '--subdir', 'DAGS_FOLDER/loan_ml_pipeline_dag.py', '--cfg-path', '/tmp/tmperdq5v_t']
[2025-06-26T14:10:12.128+0000] {standard_task_runner.py:91} INFO - Job 17: Subtask training
[2025-06-26T14:10:12.129+0000] {logging_mixin.py:188} WARNING - /home/***/.local/lib/python3.12/site-packages/***/task/task_runner/standard_task_runner.py:61 DeprecationWarning: This process (pid=845) is multi-threaded, use of fork() may lead to deadlocks in the child.
[2025-06-26T14:10:12.131+0000] {standard_task_runner.py:63} INFO - Started process 855 to run task
[2025-06-26T14:10:12.186+0000] {task_command.py:426} INFO - Running <TaskInstance: loan_credit_ml.training scheduled__2025-01-01T03:00:00+00:00 [running]> on host ab9233100691
[2025-06-26T14:10:12.314+0000] {taskinstance.py:2648} INFO - Exporting env vars: AIRFLOW_CTX_DAG_OWNER='data-team' AIRFLOW_CTX_DAG_ID='loan_credit_ml' AIRFLOW_CTX_TASK_ID='training' AIRFLOW_CTX_EXECUTION_DATE='2025-01-01T03:00:00+00:00' AIRFLOW_CTX_TRY_NUMBER='1' AIRFLOW_CTX_DAG_RUN_ID='scheduled__2025-01-01T03:00:00+00:00'
[2025-06-26T14:10:12.316+0000] {taskinstance.py:430} INFO - ::endgroup::
[2025-06-26T14:10:12.334+0000] {logging_mixin.py:188} INFO - Date config for this run: {'train_test_start_date': '2023-04-01', 'train_test_end_date': '2024-09-30', 'oot_start_date': '2024-10-01', 'oot_end_date': '2024-12-31', 'train_test_ratio': 0.8, 'model_train_date_str': '2025-01-01'}
[2025-06-26T14:10:15.036+0000] {logging_mixin.py:188} INFO - Fitting 3 folds for each of 10 candidates, totalling 30 fits
[2025-06-26T14:10:45.045+0000] {local_task_job_runner.py:124} ERROR - Received SIGTERM. Terminating subprocesses
[2025-06-26T14:10:45.154+0000] {process_utils.py:132} INFO - Sending 15 to group 855. PIDs of all processes in the group: [855]
[2025-06-26T14:10:45.159+0000] {process_utils.py:87} INFO - Sending the signal 15 to group 855
[2025-06-26T14:10:45.340+0000] {taskinstance.py:2611} ERROR - Received SIGTERM. Terminating subprocesses.
[2025-06-26T14:10:45.370+0000] {taskinstance.py:441} INFO - ::group::Post task execution logs
[2025-06-26T14:10:46.711+0000] {standard_task_runner.py:110} ERROR - Failed to execute job 17 for task training ((psycopg2.OperationalError) connection to server at "postgres" (172.23.0.2), port 5432 failed: FATAL:  the database system is shutting down

(Background on this error at: https://sqlalche.me/e/14/e3q8); 855)
[2025-06-26T14:10:46.940+0000] {process_utils.py:80} INFO - Process psutil.Process(pid=855, status='terminated', exitcode=1, started='14:10:11') (855) terminated with exit code 1
[2025-06-26T14:10:46.961+0000] {local_task_job_runner.py:240} INFO - Task exited with return code 143
[2025-06-26T14:10:46.990+0000] {taskinstance.py:3509} WARNING - Skipping mini scheduling run due to exception: None
Traceback (most recent call last):
  File "/home/airflow/.local/lib/python3.12/site-packages/sqlalchemy/engine/base.py", line 3371, in _wrap_pool_connect
    return fn()
           ^^^^
  File "/home/airflow/.local/lib/python3.12/site-packages/sqlalchemy/pool/base.py", line 327, in connect
    return _ConnectionFairy._checkout(self)
           ^^^^^^^^^^^^^^^^^^^^^^^^^^^^^^^^
  File "/home/airflow/.local/lib/python3.12/site-packages/sqlalchemy/pool/base.py", line 894, in _checkout
    fairy = _ConnectionRecord.checkout(pool)
            ^^^^^^^^^^^^^^^^^^^^^^^^^^^^^^^^
  File "/home/airflow/.local/lib/python3.12/site-packages/sqlalchemy/pool/base.py", line 493, in checkout
    rec = pool._do_get()
          ^^^^^^^^^^^^^^
  File "/home/airflow/.local/lib/python3.12/site-packages/sqlalchemy/pool/impl.py", line 256, in _do_get
    return self._create_connection()
           ^^^^^^^^^^^^^^^^^^^^^^^^^
  File "/home/airflow/.local/lib/python3.12/site-packages/sqlalchemy/pool/base.py", line 273, in _create_connection
    return _ConnectionRecord(self)
           ^^^^^^^^^^^^^^^^^^^^^^^
  File "/home/airflow/.local/lib/python3.12/site-packages/sqlalchemy/pool/base.py", line 388, in __init__
    self.__connect()
  File "/home/airflow/.local/lib/python3.12/site-packages/sqlalchemy/pool/base.py", line 690, in __connect
    with util.safe_reraise():
  File "/home/airflow/.local/lib/python3.12/site-packages/sqlalchemy/util/langhelpers.py", line 70, in __exit__
    compat.raise_(
  File "/home/airflow/.local/lib/python3.12/site-packages/sqlalchemy/util/compat.py", line 211, in raise_
    raise exception
  File "/home/airflow/.local/lib/python3.12/site-packages/sqlalchemy/pool/base.py", line 686, in __connect
    self.dbapi_connection = connection = pool._invoke_creator(self)
                                         ^^^^^^^^^^^^^^^^^^^^^^^^^^
  File "/home/airflow/.local/lib/python3.12/site-packages/sqlalchemy/engine/create.py", line 574, in connect
    return dialect.connect(*cargs, **cparams)
           ^^^^^^^^^^^^^^^^^^^^^^^^^^^^^^^^^^
  File "/home/airflow/.local/lib/python3.12/site-packages/sqlalchemy/engine/default.py", line 598, in connect
    return self.dbapi.connect(*cargs, **cparams)
           ^^^^^^^^^^^^^^^^^^^^^^^^^^^^^^^^^^^^^
  File "/home/airflow/.local/lib/python3.12/site-packages/psycopg2/__init__.py", line 122, in connect
    conn = _connect(dsn, connection_factory=connection_factory, **kwasync)
           ^^^^^^^^^^^^^^^^^^^^^^^^^^^^^^^^^^^^^^^^^^^^^^^^^^^^^^^^^^^^^^^
psycopg2.OperationalError: connection to server at "postgres" (172.23.0.2), port 5432 failed: Connection refused
	Is the server running on that host and accepting TCP/IP connections?


The above exception was the direct cause of the following exception:

Traceback (most recent call last):
  File "/home/airflow/.local/lib/python3.12/site-packages/airflow/models/taskinstance.py", line 3458, in _schedule_downstream_tasks
    ).one_or_none()
      ^^^^^^^^^^^^^
  File "/home/airflow/.local/lib/python3.12/site-packages/sqlalchemy/orm/query.py", line 2850, in one_or_none
    return self._iter().one_or_none()
           ^^^^^^^^^^^^
  File "/home/airflow/.local/lib/python3.12/site-packages/sqlalchemy/orm/query.py", line 2916, in _iter
    result = self.session.execute(
             ^^^^^^^^^^^^^^^^^^^^^
  File "/home/airflow/.local/lib/python3.12/site-packages/sqlalchemy/orm/session.py", line 1716, in execute
    conn = self._connection_for_bind(bind)
           ^^^^^^^^^^^^^^^^^^^^^^^^^^^^^^^
  File "/home/airflow/.local/lib/python3.12/site-packages/sqlalchemy/orm/session.py", line 1555, in _connection_for_bind
    return self._transaction._connection_for_bind(
           ^^^^^^^^^^^^^^^^^^^^^^^^^^^^^^^^^^^^^^^
  File "/home/airflow/.local/lib/python3.12/site-packages/sqlalchemy/orm/session.py", line 750, in _connection_for_bind
    conn = bind.connect()
           ^^^^^^^^^^^^^^
  File "/home/airflow/.local/lib/python3.12/site-packages/sqlalchemy/future/engine.py", line 412, in connect
    return super(Engine, self).connect()
           ^^^^^^^^^^^^^^^^^^^^^^^^^^^^^
  File "/home/airflow/.local/lib/python3.12/site-packages/sqlalchemy/engine/base.py", line 3325, in connect
    return self._connection_cls(self, close_with_result=close_with_result)
           ^^^^^^^^^^^^^^^^^^^^^^^^^^^^^^^^^^^^^^^^^^^^^^^^^^^^^^^^^^^^^^^
  File "/home/airflow/.local/lib/python3.12/site-packages/sqlalchemy/engine/base.py", line 96, in __init__
    else engine.raw_connection()
         ^^^^^^^^^^^^^^^^^^^^^^^
  File "/home/airflow/.local/lib/python3.12/site-packages/sqlalchemy/engine/base.py", line 3404, in raw_connection
    return self._wrap_pool_connect(self.pool.connect, _connection)
           ^^^^^^^^^^^^^^^^^^^^^^^^^^^^^^^^^^^^^^^^^^^^^^^^^^^^^^^
  File "/home/airflow/.local/lib/python3.12/site-packages/sqlalchemy/engine/base.py", line 3374, in _wrap_pool_connect
    Connection._handle_dbapi_exception_noconnection(
  File "/home/airflow/.local/lib/python3.12/site-packages/sqlalchemy/engine/base.py", line 2208, in _handle_dbapi_exception_noconnection
    util.raise_(
  File "/home/airflow/.local/lib/python3.12/site-packages/sqlalchemy/util/compat.py", line 211, in raise_
    raise exception
  File "/home/airflow/.local/lib/python3.12/site-packages/sqlalchemy/engine/base.py", line 3371, in _wrap_pool_connect
    return fn()
           ^^^^
  File "/home/airflow/.local/lib/python3.12/site-packages/sqlalchemy/pool/base.py", line 327, in connect
    return _ConnectionFairy._checkout(self)
           ^^^^^^^^^^^^^^^^^^^^^^^^^^^^^^^^
  File "/home/airflow/.local/lib/python3.12/site-packages/sqlalchemy/pool/base.py", line 894, in _checkout
    fairy = _ConnectionRecord.checkout(pool)
            ^^^^^^^^^^^^^^^^^^^^^^^^^^^^^^^^
  File "/home/airflow/.local/lib/python3.12/site-packages/sqlalchemy/pool/base.py", line 493, in checkout
    rec = pool._do_get()
          ^^^^^^^^^^^^^^
  File "/home/airflow/.local/lib/python3.12/site-packages/sqlalchemy/pool/impl.py", line 256, in _do_get
    return self._create_connection()
           ^^^^^^^^^^^^^^^^^^^^^^^^^
  File "/home/airflow/.local/lib/python3.12/site-packages/sqlalchemy/pool/base.py", line 273, in _create_connection
    return _ConnectionRecord(self)
           ^^^^^^^^^^^^^^^^^^^^^^^
  File "/home/airflow/.local/lib/python3.12/site-packages/sqlalchemy/pool/base.py", line 388, in __init__
    self.__connect()
  File "/home/airflow/.local/lib/python3.12/site-packages/sqlalchemy/pool/base.py", line 690, in __connect
    with util.safe_reraise():
  File "/home/airflow/.local/lib/python3.12/site-packages/sqlalchemy/util/langhelpers.py", line 70, in __exit__
    compat.raise_(
  File "/home/airflow/.local/lib/python3.12/site-packages/sqlalchemy/util/compat.py", line 211, in raise_
    raise exception
  File "/home/airflow/.local/lib/python3.12/site-packages/sqlalchemy/pool/base.py", line 686, in __connect
    self.dbapi_connection = connection = pool._invoke_creator(self)
                                         ^^^^^^^^^^^^^^^^^^^^^^^^^^
  File "/home/airflow/.local/lib/python3.12/site-packages/sqlalchemy/engine/create.py", line 574, in connect
    return dialect.connect(*cargs, **cparams)
           ^^^^^^^^^^^^^^^^^^^^^^^^^^^^^^^^^^
  File "/home/airflow/.local/lib/python3.12/site-packages/sqlalchemy/engine/default.py", line 598, in connect
    return self.dbapi.connect(*cargs, **cparams)
           ^^^^^^^^^^^^^^^^^^^^^^^^^^^^^^^^^^^^^
  File "/home/airflow/.local/lib/python3.12/site-packages/psycopg2/__init__.py", line 122, in connect
    conn = _connect(dsn, connection_factory=connection_factory, **kwasync)
           ^^^^^^^^^^^^^^^^^^^^^^^^^^^^^^^^^^^^^^^^^^^^^^^^^^^^^^^^^^^^^^^
sqlalchemy.exc.OperationalError: (psycopg2.OperationalError) connection to server at "postgres" (172.23.0.2), port 5432 failed: Connection refused
	Is the server running on that host and accepting TCP/IP connections?

(Background on this error at: https://sqlalche.me/e/14/e3q8)
[2025-06-26T14:10:48.999+0000] {job.py:218} ERROR - Job heartbeat got an exception
Traceback (most recent call last):
  File "/home/airflow/.local/lib/python3.12/site-packages/sqlalchemy/engine/base.py", line 3371, in _wrap_pool_connect
    return fn()
           ^^^^
  File "/home/airflow/.local/lib/python3.12/site-packages/sqlalchemy/pool/base.py", line 327, in connect
    return _ConnectionFairy._checkout(self)
           ^^^^^^^^^^^^^^^^^^^^^^^^^^^^^^^^
  File "/home/airflow/.local/lib/python3.12/site-packages/sqlalchemy/pool/base.py", line 894, in _checkout
    fairy = _ConnectionRecord.checkout(pool)
            ^^^^^^^^^^^^^^^^^^^^^^^^^^^^^^^^
  File "/home/airflow/.local/lib/python3.12/site-packages/sqlalchemy/pool/base.py", line 493, in checkout
    rec = pool._do_get()
          ^^^^^^^^^^^^^^
  File "/home/airflow/.local/lib/python3.12/site-packages/sqlalchemy/pool/impl.py", line 256, in _do_get
    return self._create_connection()
           ^^^^^^^^^^^^^^^^^^^^^^^^^
  File "/home/airflow/.local/lib/python3.12/site-packages/sqlalchemy/pool/base.py", line 273, in _create_connection
    return _ConnectionRecord(self)
           ^^^^^^^^^^^^^^^^^^^^^^^
  File "/home/airflow/.local/lib/python3.12/site-packages/sqlalchemy/pool/base.py", line 388, in __init__
    self.__connect()
  File "/home/airflow/.local/lib/python3.12/site-packages/sqlalchemy/pool/base.py", line 690, in __connect
    with util.safe_reraise():
  File "/home/airflow/.local/lib/python3.12/site-packages/sqlalchemy/util/langhelpers.py", line 70, in __exit__
    compat.raise_(
  File "/home/airflow/.local/lib/python3.12/site-packages/sqlalchemy/util/compat.py", line 211, in raise_
    raise exception
  File "/home/airflow/.local/lib/python3.12/site-packages/sqlalchemy/pool/base.py", line 686, in __connect
    self.dbapi_connection = connection = pool._invoke_creator(self)
                                         ^^^^^^^^^^^^^^^^^^^^^^^^^^
  File "/home/airflow/.local/lib/python3.12/site-packages/sqlalchemy/engine/create.py", line 574, in connect
    return dialect.connect(*cargs, **cparams)
           ^^^^^^^^^^^^^^^^^^^^^^^^^^^^^^^^^^
  File "/home/airflow/.local/lib/python3.12/site-packages/sqlalchemy/engine/default.py", line 598, in connect
    return self.dbapi.connect(*cargs, **cparams)
           ^^^^^^^^^^^^^^^^^^^^^^^^^^^^^^^^^^^^^
  File "/home/airflow/.local/lib/python3.12/site-packages/psycopg2/__init__.py", line 122, in connect
    conn = _connect(dsn, connection_factory=connection_factory, **kwasync)
           ^^^^^^^^^^^^^^^^^^^^^^^^^^^^^^^^^^^^^^^^^^^^^^^^^^^^^^^^^^^^^^^
psycopg2.OperationalError: connection to server at "postgres" (172.23.0.2), port 5432 failed: Connection refused
	Is the server running on that host and accepting TCP/IP connections?


The above exception was the direct cause of the following exception:

Traceback (most recent call last):
  File "/home/airflow/.local/lib/python3.12/site-packages/airflow/jobs/job.py", line 192, in heartbeat
    self._merge_from(Job._fetch_from_db(self, session))
                     ^^^^^^^^^^^^^^^^^^^^^^^^^^^^^^^^^
  File "/home/airflow/.local/lib/python3.12/site-packages/airflow/api_internal/internal_api_call.py", line 115, in wrapper
    return func(*args, **kwargs)
           ^^^^^^^^^^^^^^^^^^^^^
  File "/home/airflow/.local/lib/python3.12/site-packages/airflow/utils/session.py", line 76, in wrapper
    return func(*args, **kwargs)
           ^^^^^^^^^^^^^^^^^^^^^
  File "/home/airflow/.local/lib/python3.12/site-packages/airflow/utils/retries.py", line 89, in wrapped_function
    for attempt in run_with_db_retries(max_retries=retries, logger=logger, **retry_kwargs):
  File "/home/airflow/.local/lib/python3.12/site-packages/tenacity/__init__.py", line 435, in __iter__
    do = self.iter(retry_state=retry_state)
         ^^^^^^^^^^^^^^^^^^^^^^^^^^^^^^^^^^
  File "/home/airflow/.local/lib/python3.12/site-packages/tenacity/__init__.py", line 368, in iter
    result = action(retry_state)
             ^^^^^^^^^^^^^^^^^^^
  File "/home/airflow/.local/lib/python3.12/site-packages/tenacity/__init__.py", line 410, in exc_check
    raise retry_exc.reraise()
          ^^^^^^^^^^^^^^^^^^^
  File "/home/airflow/.local/lib/python3.12/site-packages/tenacity/__init__.py", line 183, in reraise
    raise self.last_attempt.result()
          ^^^^^^^^^^^^^^^^^^^^^^^^^^
  File "/usr/local/lib/python3.12/concurrent/futures/_base.py", line 449, in result
    return self.__get_result()
           ^^^^^^^^^^^^^^^^^^^
  File "/usr/local/lib/python3.12/concurrent/futures/_base.py", line 401, in __get_result
    raise self._exception
  File "/home/airflow/.local/lib/python3.12/site-packages/airflow/utils/retries.py", line 98, in wrapped_function
    return func(*args, **kwargs)
           ^^^^^^^^^^^^^^^^^^^^^
  File "/home/airflow/.local/lib/python3.12/site-packages/airflow/jobs/job.py", line 316, in _fetch_from_db
    session.merge(job)
  File "/home/airflow/.local/lib/python3.12/site-packages/sqlalchemy/orm/session.py", line 3056, in merge
    return self._merge(
           ^^^^^^^^^^^^
  File "/home/airflow/.local/lib/python3.12/site-packages/sqlalchemy/orm/session.py", line 3136, in _merge
    merged = self.get(
             ^^^^^^^^^
  File "/home/airflow/.local/lib/python3.12/site-packages/sqlalchemy/orm/session.py", line 2853, in get
    return self._get_impl(
           ^^^^^^^^^^^^^^^
  File "/home/airflow/.local/lib/python3.12/site-packages/sqlalchemy/orm/session.py", line 2975, in _get_impl
    return db_load_fn(
           ^^^^^^^^^^^
  File "/home/airflow/.local/lib/python3.12/site-packages/sqlalchemy/orm/loading.py", line 530, in load_on_pk_identity
    session.execute(
  File "/home/airflow/.local/lib/python3.12/site-packages/sqlalchemy/orm/session.py", line 1716, in execute
    conn = self._connection_for_bind(bind)
           ^^^^^^^^^^^^^^^^^^^^^^^^^^^^^^^
  File "/home/airflow/.local/lib/python3.12/site-packages/sqlalchemy/orm/session.py", line 1555, in _connection_for_bind
    return self._transaction._connection_for_bind(
           ^^^^^^^^^^^^^^^^^^^^^^^^^^^^^^^^^^^^^^^
  File "/home/airflow/.local/lib/python3.12/site-packages/sqlalchemy/orm/session.py", line 750, in _connection_for_bind
    conn = bind.connect()
           ^^^^^^^^^^^^^^
  File "/home/airflow/.local/lib/python3.12/site-packages/sqlalchemy/future/engine.py", line 412, in connect
    return super(Engine, self).connect()
           ^^^^^^^^^^^^^^^^^^^^^^^^^^^^^
  File "/home/airflow/.local/lib/python3.12/site-packages/sqlalchemy/engine/base.py", line 3325, in connect
    return self._connection_cls(self, close_with_result=close_with_result)
           ^^^^^^^^^^^^^^^^^^^^^^^^^^^^^^^^^^^^^^^^^^^^^^^^^^^^^^^^^^^^^^^
  File "/home/airflow/.local/lib/python3.12/site-packages/sqlalchemy/engine/base.py", line 96, in __init__
    else engine.raw_connection()
         ^^^^^^^^^^^^^^^^^^^^^^^
  File "/home/airflow/.local/lib/python3.12/site-packages/sqlalchemy/engine/base.py", line 3404, in raw_connection
    return self._wrap_pool_connect(self.pool.connect, _connection)
           ^^^^^^^^^^^^^^^^^^^^^^^^^^^^^^^^^^^^^^^^^^^^^^^^^^^^^^^
  File "/home/airflow/.local/lib/python3.12/site-packages/sqlalchemy/engine/base.py", line 3374, in _wrap_pool_connect
    Connection._handle_dbapi_exception_noconnection(
  File "/home/airflow/.local/lib/python3.12/site-packages/sqlalchemy/engine/base.py", line 2208, in _handle_dbapi_exception_noconnection
    util.raise_(
  File "/home/airflow/.local/lib/python3.12/site-packages/sqlalchemy/util/compat.py", line 211, in raise_
    raise exception
  File "/home/airflow/.local/lib/python3.12/site-packages/sqlalchemy/engine/base.py", line 3371, in _wrap_pool_connect
    return fn()
           ^^^^
  File "/home/airflow/.local/lib/python3.12/site-packages/sqlalchemy/pool/base.py", line 327, in connect
    return _ConnectionFairy._checkout(self)
           ^^^^^^^^^^^^^^^^^^^^^^^^^^^^^^^^
  File "/home/airflow/.local/lib/python3.12/site-packages/sqlalchemy/pool/base.py", line 894, in _checkout
    fairy = _ConnectionRecord.checkout(pool)
            ^^^^^^^^^^^^^^^^^^^^^^^^^^^^^^^^
  File "/home/airflow/.local/lib/python3.12/site-packages/sqlalchemy/pool/base.py", line 493, in checkout
    rec = pool._do_get()
          ^^^^^^^^^^^^^^
  File "/home/airflow/.local/lib/python3.12/site-packages/sqlalchemy/pool/impl.py", line 256, in _do_get
    return self._create_connection()
           ^^^^^^^^^^^^^^^^^^^^^^^^^
  File "/home/airflow/.local/lib/python3.12/site-packages/sqlalchemy/pool/base.py", line 273, in _create_connection
    return _ConnectionRecord(self)
           ^^^^^^^^^^^^^^^^^^^^^^^
  File "/home/airflow/.local/lib/python3.12/site-packages/sqlalchemy/pool/base.py", line 388, in __init__
    self.__connect()
  File "/home/airflow/.local/lib/python3.12/site-packages/sqlalchemy/pool/base.py", line 690, in __connect
    with util.safe_reraise():
  File "/home/airflow/.local/lib/python3.12/site-packages/sqlalchemy/util/langhelpers.py", line 70, in __exit__
    compat.raise_(
  File "/home/airflow/.local/lib/python3.12/site-packages/sqlalchemy/util/compat.py", line 211, in raise_
    raise exception
  File "/home/airflow/.local/lib/python3.12/site-packages/sqlalchemy/pool/base.py", line 686, in __connect
    self.dbapi_connection = connection = pool._invoke_creator(self)
                                         ^^^^^^^^^^^^^^^^^^^^^^^^^^
  File "/home/airflow/.local/lib/python3.12/site-packages/sqlalchemy/engine/create.py", line 574, in connect
    return dialect.connect(*cargs, **cparams)
           ^^^^^^^^^^^^^^^^^^^^^^^^^^^^^^^^^^
  File "/home/airflow/.local/lib/python3.12/site-packages/sqlalchemy/engine/default.py", line 598, in connect
    return self.dbapi.connect(*cargs, **cparams)
           ^^^^^^^^^^^^^^^^^^^^^^^^^^^^^^^^^^^^^
  File "/home/airflow/.local/lib/python3.12/site-packages/psycopg2/__init__.py", line 122, in connect
    conn = _connect(dsn, connection_factory=connection_factory, **kwasync)
           ^^^^^^^^^^^^^^^^^^^^^^^^^^^^^^^^^^^^^^^^^^^^^^^^^^^^^^^^^^^^^^^
sqlalchemy.exc.OperationalError: (psycopg2.OperationalError) connection to server at "postgres" (172.23.0.2), port 5432 failed: Connection refused
	Is the server running on that host and accepting TCP/IP connections?

(Background on this error at: https://sqlalche.me/e/14/e3q8)
[2025-06-26T14:10:49.054+0000] {job.py:221} ERROR - Job heartbeat failed with error. Scheduler may go into unhealthy state
[2025-06-26T14:10:49.058+0000] {local_task_job_runner.py:222} INFO - ::endgroup::
[2025-06-26T14:25:49.137+0000] {local_task_job_runner.py:120} INFO - ::group::Pre task execution logs
[2025-06-26T14:25:49.184+0000] {taskinstance.py:2076} INFO - Dependencies all met for dep_context=non-requeueable deps ti=<TaskInstance: loan_credit_ml.training scheduled__2025-01-01T03:00:00+00:00 [queued]>
[2025-06-26T14:25:49.199+0000] {taskinstance.py:2076} INFO - Dependencies all met for dep_context=requeueable deps ti=<TaskInstance: loan_credit_ml.training scheduled__2025-01-01T03:00:00+00:00 [queued]>
[2025-06-26T14:25:49.200+0000] {taskinstance.py:2306} INFO - Starting attempt 1 of 2
[2025-06-26T14:25:49.220+0000] {taskinstance.py:2330} INFO - Executing <Task(PythonOperator): training> on 2025-01-01 03:00:00+00:00
[2025-06-26T14:25:49.246+0000] {standard_task_runner.py:90} INFO - Running: ['***', 'tasks', 'run', 'loan_credit_ml', 'training', 'scheduled__2025-01-01T03:00:00+00:00', '--job-id', '17', '--raw', '--subdir', 'DAGS_FOLDER/loan_ml_pipeline_dag.py', '--cfg-path', '/tmp/tmp8hx43iqg']
[2025-06-26T14:25:49.251+0000] {standard_task_runner.py:91} INFO - Job 17: Subtask training
[2025-06-26T14:25:49.257+0000] {logging_mixin.py:188} WARNING - /home/***/.local/lib/python3.12/site-packages/***/task/task_runner/standard_task_runner.py:61 DeprecationWarning: This process (pid=856) is multi-threaded, use of fork() may lead to deadlocks in the child.
[2025-06-26T14:25:49.260+0000] {standard_task_runner.py:63} INFO - Started process 869 to run task
[2025-06-26T14:25:49.365+0000] {task_command.py:426} INFO - Running <TaskInstance: loan_credit_ml.training scheduled__2025-01-01T03:00:00+00:00 [running]> on host 0192db86dfc6
[2025-06-26T14:25:49.555+0000] {taskinstance.py:2648} INFO - Exporting env vars: AIRFLOW_CTX_DAG_OWNER='data-team' AIRFLOW_CTX_DAG_ID='loan_credit_ml' AIRFLOW_CTX_TASK_ID='training' AIRFLOW_CTX_EXECUTION_DATE='2025-01-01T03:00:00+00:00' AIRFLOW_CTX_TRY_NUMBER='1' AIRFLOW_CTX_DAG_RUN_ID='scheduled__2025-01-01T03:00:00+00:00'
[2025-06-26T14:25:49.558+0000] {taskinstance.py:430} INFO - ::endgroup::
[2025-06-26T14:25:49.597+0000] {logging_mixin.py:188} INFO - Date config for this run: {'train_test_start_date': '2023-04-01', 'train_test_end_date': '2024-09-30', 'oot_start_date': '2024-10-01', 'oot_end_date': '2024-12-31', 'train_test_ratio': 0.8, 'model_train_date_str': '2025-01-01'}
[2025-06-26T14:25:57.087+0000] {logging_mixin.py:188} INFO - Fitting 3 folds for each of 10 candidates, totalling 30 fits
[2025-06-26T14:29:15.545+0000] {logging_mixin.py:188} INFO - ✓ Model artefact saved → model_bank/credit_model_2025_01_01.pkl
[2025-06-26T14:29:16.011+0000] {python.py:237} INFO - Done. Returned value was: None
[2025-06-26T14:29:16.016+0000] {taskinstance.py:441} INFO - ::group::Post task execution logs
[2025-06-26T14:29:16.255+0000] {taskinstance.py:1206} INFO - Marking task as SUCCESS. dag_id=loan_credit_ml, task_id=training, run_id=scheduled__2025-01-01T03:00:00+00:00, execution_date=20250101T030000, start_date=20250626T142549, end_date=20250626T142916
[2025-06-26T14:29:16.619+0000] {local_task_job_runner.py:240} INFO - Task exited with return code 0
[2025-06-26T14:29:16.781+0000] {taskinstance.py:3503} INFO - 0 downstream tasks scheduled from follow-on schedule check
[2025-06-26T14:29:16.785+0000] {local_task_job_runner.py:222} INFO - ::endgroup::
